package com.zensar.assignments;

public class Test {
	int count = 0;
	void A() throws Exception {
		try {
			count++;
			System.out.println("1 :" + count);
			try {
				count++;
				System.out.println("2 :" + count);
				try {
					count++;
					System.out.println("3 :" + count);
					throw new Exception();
				}
				catch (Exception ex) {
					count++;
					System.out.println("4 :" + count);
				}
			}
			catch (Exception ex) {
				count++;
				System.out.println("5 :" + count);
			}
		}
		catch (Exception ex) {
			count++;
			System.out.println("6 :" + count);
		}
	}
	void display() {
		System.out.println(count);
	}
	public static void main(String[] args) throws Exception {
		Test obj = new Test();
		obj.A();
		obj.display();
	}
}

/*
 * class Test
 * 
 * { static void fun() { try { throw new NullPointerException("demo"); } catch
 * (NullPointerException e) { System.out.println("Caught inside fun()."); throw
 * e; // rethrowing the exception } }
 * 
 * public static void main(String args[]) { try { fun(); } catch
 * (NullPointerException e) { System.out.println("Caught in main."); } } }
 */